Workbook

Sheet DATA
A1: INDEX | B1: VERSION | C1: start | D1: end | E1: today | F1: Bienvenidos a la encuesta de agricultores para la evaluación final del proyecto: "Aumento de las medidas de resiliencia climática en los agroecosistemas del corredor seco de El Salvador (RECLIMA) - (Versión final 25UN/2026) El Salvador, junio 2026 | G1: Nombre del encuestador | H1: Nombre del supervisor | I1: Fecha de la entrevista | J1: Encuestador: rellene estos datos con la información entregada por su supervisor | K1: ¿Cuál es el nombre completo del productor? | L1: ¿Cuál es la edad del productor? | M1: ¿Cuál es el sexo del productor? | N1: ¿Cuál es el domicilio del productor? | O1: Departamento | P1: Municipio | Q1: Distrito | R1: Cantón | S1: Caserío | T1: Identificador de encuestado | U1: Encuestador: pida conversar con una persona mayor de 18 años que conozca la actividad productiva y/o económica que realiza en el hogar, así como quien pueda brindar información sobre el lugar donde habita. Recuerde que está persona puede ser o no el mismo productor. | V1: ¿Cuál es su nombre? | W1: ¿Es usted mayor de edad? | X1: ¿Hay otras personas del hogar mayores de edad que puedan brindar información sobre lo que produce? | Y1: ¿Cuál es su relación con el productor? | Z1: ¿Cuál es su relación con el productor? | AA1: Encuestador: muestre y lea el texto del consentimiento informado que tiene en papel. Si el productor o informante acepta, marque la opción "Sí". Si no acepta, marque "No" y cierre la encuesta. "Actualmente, se está llevando a cabo la evaluación final del proyecto “Aumento de las medidas de resiliencia climática en los agroecosistemas del corredor seco de El Salvador (RECLIMA)”, ejecutado por la Organización de las Naciones Unidas para la Alimentación y la Agricultura (FAO) con el fin de conocer los resultados alcanzados, las experiencias de las personas beneficiarias y las oportunidades de mejora en futuras intervenciones. En este contexto, se le invita a participar en el proceso de recopilación de información, que puede incluir encuestas, entrevistas, grupos focales y, en algunos casos, la verificación en campo de prácticas productivas implementadas en su parcela. Condiciones de participación: Su participación es totalmente voluntaria: * Puede abstenerse de responder cualquier pregunta o retirarse en cualquier momento, sin que esto le genere ningún perjuicio. * La información proporcionada será tratada de manera confidencial y utilizada únicamente con fines de análisis y evaluación. * Su participación no implica ningún costo ni beneficio económico directo. Autorización: Mediante la firma del presente documento, autorizo a la Organización de las Naciones Unidas para la Alimentación y la Agricultura (FAO) a utilizar la información proporcionada durante este proceso, exclusivamente para fines de análisis, evaluación y elaboración de informes del proyecto." | AB1: ¿El productor o informante autoriza realizar la encuesta? | AC1: Fin de encuesta | AD1: ¿El productor o algún miembro de la unidad de producción participó en el Censo Agropecuario y de Pesca 2025? | AE1: Notas del encuestador | AF1: Durante la temporada agrícola de mayo 2025 a abril 2026, ¿el productor poseía o cultivaba tierras? Incluya las tierras forestales. | AG1: ¿Cuántos TERRENOS o PARCELAS separadas una de la otra tuvo en total? | AH1: ¿Cuántos TIPOS DE CULTIVOS tuvo en total en esos terrenos o parcelas? | AI1: n_parcela_limit | AJ1: Durante la misma temporada, ¿cuánto gastaron en total por la compra de la SEMILLA de su(s) cultivo(s) en la(s) parcela(s)? | AK1: Durante la misma temporada, ¿cuánto gastaron en total por la compra de FERTILIZANTES para su(s) cultivo(s) en la(s) parcela(s)? | AL1: Sin considerar los fertilizantes, ¿cuánto gastaron en total por la compra de AGROQUÍMICOS para su(s) cultivo(s) en la(s) parcela(s) durante esa temporada? | AM1: Durante la misma temporada, ¿cuánto gastaron en total por contratación de mano de obra o jornales para su(s) cultivo(s) en la(s) parcela(s)? | AN1: Durante esa temporada, ¿Cuánto fue el ingreso total obtenido por la venta de su(s) cultivo(s) en la(s) parcela(s)? | AO1: Durante la temporada agrícola de mayo 2025 a abril 2026, ¿usted poseía ganado de alguno de los siguientes grupos? | AP1: Durante la temporada agrícola de mayo 2025 a abril 2026, ¿usted poseía ganado de alguno de los siguientes grupos?/Bovinos (vacas, terneros, novillos, bueyes, toros) | AQ1: Durante la temporada agrícola de mayo 2025 a abril 2026, ¿usted poseía ganado de alguno de los siguientes grupos?/Porcinos (cerdos) | AR1: Durante la temporada agrícola de mayo 2025 a abril 2026, ¿usted poseía ganado de alguno de los siguientes grupos?/Aves (gallinas, pollos, gallos) | AS1: Durante la temporada agrícola de mayo 2025 a abril 2026, ¿usted poseía ganado de alguno de los siguientes grupos?/Cabras | AT1: Durante la temporada agrícola de mayo 2025 a abril 2026, ¿usted poseía ganado de alguno de los siguientes grupos?/Equinos (caballos, burros, mulas) | AU1: Durante la temporada agrícola de mayo 2025 a abril 2026, ¿usted poseía ganado de alguno de los siguientes grupos?/Equinos (caballos, burros, mulas) | AV1: ¿Nos pude confirmar que el productor aceptó ser parte del proyecto RECLIMA? | AW1: ¿Cuándo inició usted o el productor su participación en el proyecto RECLIMA? | AX1: ¿El productor participó de la Escuela de Campo para Agricultores? | AY1: ¿El productor participó en el desarrollo de planes de finca? | AZ1: ¿Cuál era el nombre del Promotor Comunitario de la Escuale de Campo para Agricultores? | BA1: ¿El productor participó en las actividades de restauración de la vegetación de las áreas cercanas fuera de su parcela? | BB1: Durante la temporada agrícola de mayo 2025 a abril 2026, ¿en qué tipo de prácticas de restauración de ecosistemas participó el productor fuera de su parcela? | BC1: Durante la temporada agrícola de mayo 2025 a abril 2026, ¿su comunidad cuenta con un vivero activo para producir plantas forestales? | BD1: Durante la temporada agrícola de mayo 2025 a abril 2026, ¿el productor recibió asesoramiento técnico relacionado a las actividades de restauración de ecosistemas fuera de su parcela? | BE1: Durante la temporada agrícola de mayo 2025 a abril 2026, ¿qué institución le brindó asistencia técnica? | BF1: Durante la temporada agrícola de mayo 2025 a abril 2026, ¿qué institución le brindó asistencia técnica?/Entidad de gobierno central | BG1: Durante la temporada agrícola de mayo 2025 a abril 2026, ¿qué institución le brindó asistencia técnica?/RECLIMA | BH1: Durante la temporada agrícola de mayo 2025 a abril 2026, ¿qué institución le brindó asistencia técnica?/Organismo Internacional | BI1: Durante la temporada agrícola de mayo 2025 a abril 2026, ¿qué institución le brindó asistencia técnica?/ONG | BJ1: Durante la temporada agrícola de mayo 2025 a abril 2026, ¿qué institución le brindó asistencia técnica?/Asociación de productores | BK1: Durante la temporada agrícola de mayo 2025 a abril 2026, ¿qué institución le brindó asistencia técnica?/Cooperativa | BL1: Después de aplicar las medidas de restauración en la temporada agrícola de mayo 2025 a abril 2026, la disponibilidad de agua en la comunidad… | BM1: Durante la temporada agrícola de mayo 2025 a abril 2026, ¿cuál considera que fue la mayor amenaza para los árboles recién plantados en las zonas de restauración de su comunidad? | BN1: Especifique | BO1: Durante la temporada agrícola de mayo 2025 a abril 2026, ¿usted o algún miembro de la unidad de producción u hogar, ya sea propio o en sociedad, tuvo...? | BP1: Durante la temporada agrícola de mayo 2025 a abril 2026, ¿usted o algún miembro de la unidad de producción u hogar, ya sea propio o en sociedad, tuvo...?/Tractor | BQ1: Durante la temporada agrícola de mayo 2025 a abril 2026, ¿usted o algún miembro de la unidad de producción u hogar, ya sea propio o en sociedad, tuvo...?/Rastra | BR1: Durante la temporada agrícola de mayo 2025 a abril 2026, ¿usted o algún miembro de la unidad de producción u hogar, ya sea propio o en sociedad, tuvo...?/Cultivadora | BS1: Durante la temporada agrícola de mayo 2025 a abril 2026, ¿usted o algún miembro de la unidad de producción u hogar, ya sea propio o en sociedad, tuvo...?/Sembradora | BT1: Durante la temporada agrícola de mayo 2025 a abril 2026, ¿usted o algún miembro de la unidad de producción u hogar, ya sea propio o en sociedad, tuvo...?/Podadora | BU1: Durante la temporada agrícola de mayo 2025 a abril 2026, ¿usted o algún miembro de la unidad de producción u hogar, ya sea propio o en sociedad, tuvo...?/Equipo de fumigación | BV1: Durante la temporada agrícola de mayo 2025 a abril 2026, ¿usted o algún miembro de la unidad de producción u hogar, ya sea propio o en sociedad, tuvo...?/Tanque para almacenamiento de agua | BW1: Durante la temporada agrícola de mayo 2025 a abril 2026, ¿usted o algún miembro de la unidad de producción u hogar, ya sea propio o en sociedad, tuvo...?/Bomba de agua | BX1: Durante la temporada agrícola de mayo 2025 a abril 2026, ¿usted o algún miembro de la unidad de producción u hogar, ya sea propio o en sociedad, tuvo...?/Equipo para la cría o engorda de animales | BY1: Durante la temporada agrícola de mayo 2025 a abril 2026, ¿usted o algún miembro de la unidad de producción u hogar, ya sea propio o en sociedad, tuvo...?/Autos particulares | BZ1: Durante la temporada agrícola de mayo 2025 a abril 2026, ¿usted o algún miembro de la unidad de producción u hogar, ya sea propio o en sociedad, tuvo...?/Camioneta o camión | CA1: Durante la temporada agrícola de mayo 2025 a abril 2026, ¿usted o algún miembro de la unidad de producción u hogar, ya sea propio o en sociedad, tuvo...?/Bodega | CB1: Durante la temporada agrícola de mayo 2025 a abril 2026, ¿usted o algún miembro de la unidad de producción u hogar, ya sea propio o en sociedad, tuvo...?/Ningún activo | CC1: Durante la temporada agrícola de mayo 2025 a abril 2026, ¿perdieron toda o parte de la cosecha o de sus animales por… | CD1: Durante la temporada agrícola de mayo 2025 a abril 2026, ¿perdieron toda o parte de la cosecha o de sus animales por…/Plagas o enfermedades | CE1: Durante la temporada agrícola de mayo 2025 a abril 2026, ¿perdieron toda o parte de la cosecha o de sus animales por…/Sequías | CF1: Durante la temporada agrícola de mayo 2025 a abril 2026, ¿perdieron toda o parte de la cosecha o de sus animales por…/Lluvia o inundaciones | CG1: Durante la temporada agrícola de mayo 2025 a abril 2026, ¿perdieron toda o parte de la cosecha o de sus animales por…/Heladas y granizadas | CH1: Durante la temporada agrícola de mayo 2025 a abril 2026, ¿perdieron toda o parte de la cosecha o de sus animales por…/Vientos fuertes | CI1: Durante la temporada agrícola de mayo 2025 a abril 2026, ¿perdieron toda o parte de la cosecha o de sus animales por…/Derrumbes | CJ1: Durante la temporada agrícola de mayo 2025 a abril 2026, ¿perdieron toda o parte de la cosecha o de sus animales por…/Incendios | CK1: Durante la temporada agrícola de mayo 2025 a abril 2026, ¿perdieron toda o parte de la cosecha o de sus animales por…/Robo | CL1: Durante la temporada agrícola de mayo 2025 a abril 2026, ¿perdieron toda o parte de la cosecha o de sus animales por…/No sufrió pérdidas de cosecha o animales | CM1: ¿Cuántas personas habitan al día de hoy el hogar del productor? | CN1: Enliste los nombres de pila de los miembros que integran el hogar del productor empezando con el jefe o jefa del hogar. Recuerde registrar a los recien nacidos, ancianos y aquellas personas que al momento de la encuesta se encuentran temporalmente ausentes por motivo de trabajo, vacaciones, enfermedad, etc. | CO1: Durante la temporada agrícola de mayo 2025 a abril 2026, ¿cuál es la principal fuente de ingresos económicos del hogar del productor? | CP1: ¿En los últimos TRES MESES, por falta de dinero u otros recursos alguna vez usted se preocupó porque los alimentos se acabaran en su hogar? | CQ1: ¿En los últimos TRES MESES, por falta de dinero u otros recursos alguna vez en su hogar se quedaron sin alimentos? | CR1: ¿En los últimos TRES MESES, por falta de dinero u otros recursos alguna vez en su hogar dejaron de tener una alimentación saludable*? | CS1: ¿En los últimos TRES MESES, por falta de dinero u otros recursos alguna vez usted o algún adulto en su hogar tuvo una alimentación basada en poca variedad de alimentos? | CT1: ¿En los últimos TRES MESES, por falta de dinero u otros recursos alguna vez usted o algún adulto en su hogar dejó de desayunar, almorzar o cenar? | CU1: ¿En los últimos TRES MESES, por falta de dinero u otros recursos alguna vez usted o algún adulto en su hogar comió menos de lo que debía comer? | CV1: ¿En los últimos TRES MESES, por falta de dinero u otros recursos alguna vez usted o algún adulto en su hogar sintió hambre pero no comió? | CW1: ¿En los últimos TRES MESES, por falta de dinero u otros recursos alguna vez usted o algún adulto en su hogar solo comió una vez al día o dejó de comer durante todo un día? | CX1: ¿En su hogar viven personas menores de 18 años? | CY1: ¿En los últimos TRES MESES, por falta de dinero u otros recursos, alguna vez algún menor de 18 años en su hogar dejó de tener una alimentación saludable y balanceada? | CZ1: ¿En los últimos TRES MESES, por falta de dinero u otros recursos, alguna vez algún menor de 18 años en su hogar tuvo una alimentación basada en poca variedad de alimentos? | DA1: ¿En los últimos TRES MESES, por falta de dinero u otros recursos, alguna vez algún menor de 18 años de su hogar dejó de desayunar, almorzar o cenar? | DB1: ¿En los últimos TRES MESES, por falta de dinero u otros recursos, alguna vez algún menor de 18 años de su hogar comió menos de lo que debía? | DC1: ¿En los últimos TRES MESES, por falta de dinero u otros recursos, alguna vez tuvieron que disminuir la cantidad servida en las comidas a algún menor de 18 años en su hogar? | DD1: ¿En los últimos TRES MESES, por falta de dinero u otros recursos, alguna vez algún menor de 18 años en su hogar sintió hambre pero no comió? | DE1: ¿En los últimos TRES MESES, por falta de dinero u otros recursos, alguna vez algún menor de 18 años en su hogar solo comió una vez al día o dejó de comer todo un día? | DF1: En la última semana, ¿Cuántos días los miembros del hogar del productor consumieron los siguientes grupos de alimentos...? | DG1: CEREALES Y TUBÉRCULOS | DH1: LEGUMINOSAS, NUECES y SEMILLAS SECAS | DI1: PRODUCTOS LÁCTEOS | DJ1: PRODUCTOS CÁRNICOS | DK1: VEGETALES | DL1: FRUTAS | DM1: ACEITES / GRASAS o MANTEQUILLA | DN1: AZÚCAR O DULCES | DO1: En su hogar, ¿tienen acceso a fuentes de agua? | DP1: ¿Qué tipo de fuente de agua posee? | DQ1: Especifique | DR1: ¿Esa fuente de agua es confiable? | DS1: ¿Esa fuente de agua es segura? | DT1: ¿En qué meses del año tiene mayor acceso a agua? | DU1: ¿En qué meses del año tiene mayor acceso a agua?/Ene | DV1: ¿En qué meses del año tiene mayor acceso a agua?/Feb | DW1: ¿En qué meses del año tiene mayor acceso a agua?/Mar | DX1: ¿En qué meses del año tiene mayor acceso a agua?/Abr | DY1: ¿En qué meses del año tiene mayor acceso a agua?/May | DZ1: ¿En qué meses del año tiene mayor acceso a agua?/Jun | EA1: ¿En qué meses del año tiene mayor acceso a agua?/Jul | EB1: ¿En qué meses del año tiene mayor acceso a agua?/Ago | EC1: ¿En qué meses del año tiene mayor acceso a agua?/Sep | ED1: ¿En qué meses del año tiene mayor acceso a agua?/Oct | EE1: ¿En qué meses del año tiene mayor acceso a agua?/Nov | EF1: ¿En qué meses del año tiene mayor acceso a agua?/Dic | EG1: Encuestador: muestre y lea al productor o informante clave el segundo consentimiento referido al registro de la ubicación y área de la parcela principal. "Hemos finalizada la recolección de datos sobre su parcela, cultivos y hogar del productor. La evaluación también requiere registrar la ubicación y el área de la parcela principal mediante un dispositivo GPS. Por lo tanto, quisiéramos invitarlo a participar en este proceso que consiste en que un técnico recorrerá el perímetro o los puntos principales de la parcela usando una aplicación móvil para obtener su forma y área aproximadas. Es importante que sepa que esta información se utilizará únicamente con fines analíticos para evaluar el proyecto RECLIMA y, por lo tanto, no constituye un trámite legal ni define límites de propiedad ni tiene efectos sobre la tenencia de la tierra. Al igual que en la encuesta, su participación es totalmente voluntaria, lo que implica que: * Puede abstenerse del registro de la ubicación y del área de la parcela principal, sin que ello le genere ningún perjuicio. * La información proporcionada será tratada de manera confidencial y utilizada únicamente con fines de análisis y evaluación. * Su participación no implica ningún costo ni beneficio económico directo. Autorización: Mediante la firma del presente documento, autorizo a la Organización de las Naciones Unidas para la Alimentación y la Agricultura (FAO) a utilizar la información proporcionada durante este proceso exclusivamente con fines de análisis, evaluación y elaboración de informes del proyecto." | EH1: ¿El productor o informante autoriza registrar las coordenadas de la parcela donde se encuentra? | EI1: Registre las coordenadas de la esquina de la parcela | EJ1: Si no registró las coordenadas GPS, especifique el motivo | EK1: ¿Cuál es el número de teléfono del productor? | EL1: ¿Podría darnos otro número de contacto o correo electrónico del productor? | EM1: Hemos llegado al final de la encuesta. Le agradecemos su participación y le deseamos un buen día. Hasta luego. | EN1: Encuestador, incluya notas o comentarios si los tiene. | EO1: Si respuesta es No, pause la encuesta y pida hablar con productor o informante | EP1: ¿Cuál es su función en las actividades agrícolas, pecuarias o forestales? | EQ1: Durante la (temporada agrícola de mayo 2025 a abril 2026), ¿cuál es la principal fuente de ingresos económicos en su hogar? | ER1: ¿Recuerda el nombre del Promotor Comunitario de su Escuela de Campo? | ES1: _id | ET1: _uuid | EU1: _submission_time | EV1: _validation_status | EW1: _notes | EX1: _status | EY1: _submitted_by | EZ1: __version__ | FA1: _tags | FB1: meta/rootUuid | FC1: KoboIndex
A2: ="V"&B2&"-R"&FC2 -> V1-R1 | B2: 1 | C2: 46199.414 | D2: 46199.419 | E2: 46199 | G2: William | H2: Rigoberto | I2: 46199 | K2: ANA YESENIA REYES AGUIRRE | L2: 40 | M2: Mujer | O2: La Paz | P2: La Paz Centro | Q2: San Juan Tepezontes | R2: LOS LAURELES | S2: LOS LAURELES | V2: ANA YESENIA REYESAGUIRRE | W2: Sí | Y2: Productor | AB2: Sí | AD2: No sabe / no responde | AF2: No | EK2: 78077117 | ES2: 22169725 | ET2: c27bf41a-5a46-4ff0-8891-ba6f899821e0 | EU2: 46199.669 | EX2: submitted_via_web | EY2: encuestador_adepro | EZ2: vx3xVKqsiQtpxk6VuQQ43v | FB2: uuid:c27bf41a-5a46-4ff0-8891-ba6f899821e0 | FC2: 1
A3: ="V"&B3&"-R"&FC3 -> V1-R2 | B3: 1 | C3: 46199.432 | D3: 46199.436 | E3: 46199 | G3: Wendy | H3: Rigoberto | I3: 46199 | K3: VICENTE HERNANDEZ | L3: 63 | M3: Hombre | O3: La Paz | R3: SAN JERONIMO | S3: SAN JERONIMO | V3: VICENTE HERNANDEZ | W3: Sí | AB3: Sí | AF3: No | EH3: Sí | EI3: PENDIENTE | EK3: 74263711 | ES3: 22170005 | ET3: 68e6f4cb-93f4-4199-b80b-31248180af63 | EU3: 46199.698 | EX3: submitted_via_web | EY3: encuestador_adepro | EZ3: vx3xVKqsiQtpxk6VuQQ43v | FB3: uuid:68e6f4cb-93f4-4199-b80b-31248180af63 | FC3: 2
A4: ="V"&B4&"-R"&FC4 -> V1-R3 | B4: 1 | C4: 46199.437 | D4: 46199.448 | E4: 46199 | V4: VICENTE HERNANDEZ | W4: Sí | AB4: Sí | AD4: Sí | AF4: No | EH4: Sí | EI4: 13.5302145 -88.907325 0.0 0.0;13.538104792939846 -88.89374367892742 0.0 0.0;13.545652935769432 -88.88331055641174 0.0 0.0;13.552622621472658 -88.86587116867304 0.0 0.0;13.544064576342993 -88.86467322707176 0.0 0.0;13.533598023217413 -88.85741081088781 0.0 0.0;13.52911203041512 -88.8476700335741 0.0 0.0;13.519300704714041 -88.84321823716164 0.0 0.0;13.508328740164771 -88.85714024305344 0.0 0.0;13.5302145 -88.907325 0.0 0.0 | EK4: 74263031 | ES4: 22170006 | ET4: d17de3ac-af9a-4c3c-aacb-113ffdeb3ef5 | EU4: 46199.698 | EX4: submitted_via_web | EY4: encuestador_adepro | EZ4: vx3xVKqsiQtpxk6VuQQ43v | FB4: uuid:d17de3ac-af9a-4c3c-aacb-113ffdeb3ef5 | FC4: 3
A5: ="V"&B5&"-R"&FC5 -> V1-R4 | B5: 1 | C5: 46199.464 | D5: 46199.474 | E5: 46199 | G5: Iván | H5: Milagro | I5: 46199 | K5: ELIA DEL CARMEN PORTILLO | L5: 83 | M5: Mujer | O5: La Paz | P5: La Paz Centro | Q5: El Rosario | R5: EL TUNAL | S5: LA COQUERA | V5: ELIA PORTILLO | W5: Sí | Y5: Productor | AB5: Sí | AD5: No | AF5: No | EH5: Sí | EI5: 13.5000084 -89.004493 0.0 0.0;13.5000944 -89.0046434 0.0 0.0;13.5002997 -89.0044582 0.0 0.0;13.5002343 -89.0043771 0.0 0.0;13.5000084 -89.004493 0.0 0.0 | EK5: 68542233 | ES5: 22324058 | ET5: 37111e0c-945e-4344-bb3e-3dc046ff4190 | EU5: 46211.125 | EX5: submitted_via_web | EY5: encuestador_adepro | EZ5: vx3xVKqsiQtpxk6VuQQ43v | FB5: uuid:37111e0c-945e-4344-bb3e-3dc046ff4190 | FC5: 4
A6: ="V"&B6&"-R"&FC6 -> V1-R5 | B6: 1 | C6: 46199.352 | D6: 46199.365 | E6: 46199 | G6: Iván | H6: Milagro | I6: 46199 | K6: GERSON ANTONIO PEREZ | L6: 25 | M6: Hombre | O6: La Paz | P6: La Paz Centro | Q6: El Rosario | R6: EL TUNAL | S6: PUENTE VIEJO | V6: GERSON PEREZ | W6: Sí | Y6: Productor | AB6: Sí | AF6: No | EH6: No | EJ6: Lejanía, dentro del distritio | EK6: 60776103 | ES6: 22325150 | ET6: 0847d69c-3f4c-4045-a801-cdfdc6a97c0b | EU6: 46211.166 | EX6: submitted_via_web | EY6: encuestador_adepro | EZ6: vx3xVKqsiQtpxk6VuQQ43v | FB6: uuid:0847d69c-3f4c-4045-a801-cdfdc6a97c0b | FC6: 5
A7: ="V"&B7&"-R"&FC7 -> V2-R1 | B7: 2 | C7: 46202.371 | D7: 46202.416 | E7: 46201 | G7: Javier | H7: Milagro | I7: 46202 | K7: WILLIAM GEOVANNY RIVERA AYALA | L7: 29 | M7: Hombre | O7: Usulután | P7: Usulután Oeste | Q7: Jiquilisco | R7: COMUNIDAD LOS LOTES | V7: WILLIAM GEOVANNY RIVERA AYALA | W7: Sí | Y7: Productor | AB7: Sí | AD7: Sí | AF7: Sí | AG7: 1 | AH7: 1 | AI7: 1 | AJ7: 50 | AK7: 40 | AL7: 200 | AM7: 90 | AN7: 250 | AV7: Sí | AW7: 2020 | AX7: Sí | AY7: No | AZ7: SARAI EMERITA | BA7: Sí | BB7: Regeneración artificial (plantación de árboles) | BC7: No | BD7: No | BL7: Sin cambió | BM7: Otra, especificar | BN7: PLAGAS | BO7: Tractor Equipo de fumigación | BP7: 1 | BQ7: 0 | BR7: 0 | BS7: 0 | BT7: 0 | BU7: 1 | BV7: 0 | BW7: 0 | BX7: 0 | BY7: 0 | BZ7: 0 | CA7: 0 | CB7: 0 | CC7: Sequías | CD7: 0 | CE7: 1 | CF7: 0 | CG7: 0 | CH7: 0 | CI7: 0 | CJ7: 0 | CK7: 0 | CL7: 0 | CM7: 2 | CO7: Oficios varios (artesanías, carpintería, albañilería, etc.) | CP7: Sí | CQ7: No | CR7: No | CS7: No | CT7: No | CU7: No | CV7: No | CW7: No | CX7: No | DG7: 5 | DH7: 0 | DI7: 3 | DJ7: 1 | DK7: 2 | DL7: 3 | DM7: 6 | DN7: 7 | DO7: Sí | DP7: Pozo | DR7: Sí | DS7: Sí | DT7: Jul | DU7: 0 | DV7: 0 | DW7: 0 | DX7: 0 | DY7: 0 | DZ7: 0 | EA7: 1 | EB7: 0 | EC7: 0 | ED7: 0 | EE7: 0 | EF7: 0 | EH7: Sí | EI7: 13.390987 -88.668225 40.74118598854011 10.495014000000001;13.390987 -88.668225 40.74118598854011 10.495014000000001;13.390987 -88.668225 40.74118598854011 10.495014000000001;13.390987 -88.668225 40.74118598854011 10.495014000000001;13.390987 -88.668225 40.74118598854011 10.495014000000001;13.390987 -88.668225 40.74118598854011 10.495014000000001;13.390987 -88.668225 40.74118598854011 10.495014000000001;13.390987 -88.668225 40.74118598854011 10.495014000000001;13.390987 -88.668225 40.74118598854011 10.495014000000001;13.390987 -88.668225 40.74118598854011 10.495014000000001;13.390987 -88.668225 40.74118598854011 10.495014000000001;13.390987 -88.668225 40.74118598854011 10.495014000000001;13.390987 -88.668225 40.74118598854011 10.495014000000001;13.390987 -88.668225 40.74118598854011 10.495014000000001;13.390987 -88.668225 40.74118598854011 10.495014000000001;13.390987 -88.668225 40.74118598854011 10.495014000000001;13.390987 -88.668225 40.74118598854011 10.495014000000001;13.390987 -88.668225 40.74118598854011 10.495014000000001;13.390987 -88.668225 40.74118598854011 10.495014000000001;13.390987 -88.668225 40.74118598854011 10.495014000000001;13.390987 -88.668225 40.74118598854011 10.495014000000001;13.390987 -88.668225 40.74118598854011 10.495014000000001;13.390987 -88.668225 40.74118598854011 10.495014000000001;13.390987 -88.668225 40.74118598854011 10.495014000000001;13.390987 -88.668225 40.74118598854011 10.495014000000001;13.390987 -88.668225 40.74118598854011 10.495014000000001;13.390987 -88.668225 40.74118598854011 10.495014000000001;13.390987 -88.668225 40.74118598854011 10.495014000000001;13.390987 -88.668225 40.74118598854011 10.495014000000001;13.390987 -88.668225 40.74118598854011 10.495014000000001;13.390987 -88.668225 40.74118598854011 10.495014000000001;13.390987 -88.668225 40.74118598854011 10.495014000000001;13.390987 -88.668225 40.74118598854011 10.495014000000001;13.390987 -88.668225 40.74118598854011 10.495014000000001;13.390987 -88.668225 40.74118598854011 10.495014000000001;13.390987 -88.668225 40.74118598854011 10.495014000000001;13.390987 -88.668225 40.74118598854011 10.495014000000001;13.390987 -88.668225 40.74118598854011 10.495014000000001;13.390987 -88.668225 40.74118598854011 10.495014000000001;13.390987 -88.668225 40.74118598854011 10.495014000000001;13.390987 -88.668225 40.74118598854011 10.495014000000001;13.390987 -88.668225 40.74118598854011 10.495014000000001;13.390987 -88.668225 40.74118598854011 10.495014000000001;13.390987 -88.668225 40.74118598854011 10.495014000000001;13.390987 -88.668225 40.74118598854011 10.495014000000001;13.390987 -88.668225 40.74118598854011 10.495014000000001;13.390987 -88.668225 40.74118598854011 10.495014000000001;13.390987 -88.668225 40.74118598854011 10.495014000000001;13.390987 -88.668225 40.74118598854011 10.495014000000001 | EK7: 63009520 | EL7: 79634644 | EN7: NINGUNO | ES7: 22204810 | ET7: c98c95d6-65c9-4baf-881b-81a1715fc4c6 | EU7: 46202.678 | EX7: submitted_via_web | EY7: adepro | EZ7: vzzpoqrQEmZ8kFXEawwS6F | FB7: uuid:c98c95d6-65c9-4baf-881b-81a1715fc4c6 | FC7: 1
A8: ="V"&B8&"-R"&FC8 -> V2-R2 | B8: 2 | C8: 46202.416 | D8: 46202.449 | E8: 46201 | G8: Javier | H8: Milagro | I8: 46202 | K8: JONATHAN ALEJANDRO AMAYA CLIMACO | L8: 33 | M8: Hombre | O8: Usulután | P8: Usulután Oeste | Q8: Jiquilisco | R8: LA NORIA | V8: JONATHAN ALEJANDRO AMAYA CLIMACO | W8: Sí | Y8: Productor | AB8: Sí | AD8: Sí | AF8: Sí | AG8: 1 | AH8: 3 | AI8: 1 | AJ8: 300 | AK8: 150 | AL8: 30 | AM8: 50 | AN8: 600 | AV8: Sí | AW8: 2020 | AX8: Sí | AY8: Sí | AZ8: NO SABE | BA8: No | BO8: Ningún activo | BP8: 0 | BQ8: 0 | BR8: 0 | BS8: 0 | BT8: 0 | BU8: 0 | BV8: 0 | BW8: 0 | BX8: 0 | BY8: 0 | BZ8: 0 | CA8: 0 | CB8: 1 | CC8: Sequías | CD8: 0 | CE8: 1 | CF8: 0 | CG8: 0 | CH8: 0 | CI8: 0 | CJ8: 0 | CK8: 0 | CL8: 0 | CM8: 1 | CO8: Jornalero agropecuario | CP8: Sí | CQ8: No | CR8: No | CS8: No | CT8: No | CU8: No | CV8: No | CW8: No | CX8: No | DG8: 3 | DH8: 2 | DI8: 7 | DJ8: 2 | DK8: 3 | DL8: 3 | DM8: 7 | DN8: 7 | DO8: Sí | DP8: Pozo | DR8: Sí | DS8: Sí | DT8: Ago | DU8: 0 | DV8: 0 | DW8: 0 | DX8: 0 | DY8: 0 | DZ8: 0 | EA8: 0 | EB8: 1 | EC8: 0 | ED8: 0 | EE8: 0 | EF8: 0 | EH8: Sí | EI8: 13.385908 -88.67585 31.642824482172728 4.7486515301917995;13.385633 -88.675305 0 0;13.38606 -88.675058 0 0;13.3864 -88.675058 0 0;13.386927 -88.675144 0 0;13.387125 -88.67552 0 0;13.386895 -88.675928 0 0;13.386661 -88.676131 0 0;13.386462 -88.676233 0 0;13.385977 -88.675917 0 0;13.385908 -88.67585 31.642824482172728 4.7486515301917995 | EK8: 79592066 | EN8: NINGUNO | ES8: 22205258 | ET8: 6f0cebe3-270d-4422-a021-d10d5811ee1d | EU8: 46202.699 | EX8: submitted_via_web | EY8: adepro | EZ8: vzzpoqrQEmZ8kFXEawwS6F | FB8: uuid:6f0cebe3-270d-4422-a021-d10d5811ee1d | FC8: 2
A9: ="V"&B9&"-R"&FC9 -> V2-R3 | B9: 2 | C9: 46202.505 | D9: 46202.529 | E9: 46202 | G9: Juan | H9: Rigoberto | K9: JUAN PABLO CARRANZA GIRON | L9: 42 | M9: Hombre | O9: San Miguel | P9: San Miguel Oeste | Q9: El Transito | R9: CALLE NUEVA | S9: LA LINEA | V9: JUAN PABLO CARRANZA | W9: Sí | AB9: Sí | AD9: No | AF9: Sí | AG9: 1 | AH9: 1 | AI9: 1 | AJ9: 45 | AK9: 100 | AL9: 50 | AM9: 150 | AV9: Sí | AW9: 2025 | AX9: No | AY9: No | BA9: No | BO9: Arado Equipo de fumigación | BP9: 0 | BQ9: 0 | BR9: 0 | BS9: 0 | BT9: 0 | BU9: 1 | BV9: 0 | BW9: 0 | BX9: 0 | BY9: 0 | BZ9: 0 | CA9: 0 | CB9: 0 | CC9: Sequías Vientos fuertes | CD9: 0 | CE9: 1 | CF9: 0 | CG9: 0 | CH9: 1 | CI9: 0 | CJ9: 0 | CK9: 0 | CL9: 0 | CM9: 5 | CO9: Producción agropecuaria | CP9: Sí | CQ9: Sí | CR9: Sí | CS9: Sí | CT9: No | CU9: Sí | CV9: Sí | CW9: Sí | CX9: Sí | CY9: Sí | CZ9: Sí | DA9: No | DB9: Sí | DC9: Sí | DD9: No | DE9: No | DG9: 7 | DH9: 0 | DI9: 7 | DJ9: 3 | DK9: 0 | DL9: 7 | DM9: 7 | DN9: 7 | DO9: Sí | DP9: Pozo | DR9: Sí | DS9: No | DT9: Ene Feb Mar Abr Ago Jun Jul May Sep Oct Nov Dic | DU9: 1 | DV9: 1 | DW9: 1 | DX9: 1 | DY9: 1 | DZ9: 1 | EA9: 1 | EB9: 1 | EC9: 1 | ED9: 1 | EE9: 1 | EF9: 1 | EH9: No | EJ9: Otra | EK9: 74182063 | EL9: 74182063 | EN9: NO SE MIDIO LA PARCELA POR MOTIVOS DE HERENCIA QUE NO ESTA DEFINIDO LA DIVISION DEL TERRENO | ES9: 22206850 | ET9: 62ca324f-4710-41b1-bef2-add9a128d1e7 | EU9: 46202.789 | EX9: submitted_via_web | EY9: encuestador_adepro | EZ9: vzzpoqrQEmZ8kFXEawwS6F | FB9: uuid:62ca324f-4710-41b1-bef2-add9a128d1e7 | FC9: 3
A10: ="V"&B10&"-R"&FC10 -> V2-R4 | B10: 2 | C10: 46202.562 | D10: 46202.588 | E10: 46202 | G10: Juan | H10: Rigoberto | K10: GERTRUDIS CRUZ CRUZ | L10: 33 | M10: Hombre | O10: San Miguel | P10: San Miguel Oeste | Q10: El Transito | R10: CALLE NUEVA | S10: SAN CARLOS | V10: GERTRUDIS CRUZ CRUZ | W10: Sí | AB10: Sí | AD10: No | AF10: Sí | AG10: 1 | AH10: 1 | AI10: 1 | AJ10: 60 | AK10: 300 | AL10: 50 | AM10: 75 | AN10: 250 | AV10: Sí | AW10: 2025 | AX10: No | AY10: No | BA10: No | BO10: Bomba de agua Equipo de fumigación | BP10: 0 | BQ10: 0 | BR10: 0 | BS10: 0 | BT10: 0 | BU10: 1 | BV10: 0 | BW10: 1 | BX10: 0 | BY10: 0 | BZ10: 0 | CA10: 0 | CB10: 0 | CC10: No sufrió pérdidas de cosecha o animales | CD10: 0 | CE10: 0 | CF10: 0 | CG10: 0 | CH10: 0 | CI10: 0 | CJ10: 0 | CK10: 0 | CL10: 1 | CM10: 6 | CO10: Jornalero agropecuario | CP10: Sí | CQ10: No | CR10: No | CS10: No | CT10: No | CU10: No | CV10: No | CW10: No | CX10: Sí | CY10: No | CZ10: No | DA10: No | DB10: No | DC10: No | DD10: No | DE10: No | DG10: 4 | DH10: 0 | DI10: 4 | DJ10: 2 | DK10: 5 | DL10: 7 | DM10: 7 | DN10: 1 | DO10: Sí | EH10: Sí | EI10: 13.3740134 -88.278169 0.0 0.0;13.3748247 -88.2782237 0.0 0.0;13.3748013 -88.2776332 0.0 0.0;13.374145 -88.2776854 0.0 0.0;13.3740134 -88.278169 0.0 0.0 | EK10: 73127467 | EL10: 73127467 | EN10: NINGUNO | ES10: 22207297 | ET10: 4dc24167-1b02-4ff6-b174-9fd59b2cef2c | EU10: 46202.839 | EX10: submitted_via_web | EY10: encuestador_adepro | EZ10: vzzpoqrQEmZ8kFXEawwS6F | FB10: uuid:4dc24167-1b02-4ff6-b174-9fd59b2cef2c | FC10: 4
A11: ="V"&B11&"-R"&FC11 -> V2-R5 | B11: 2 | C11: 46202.723 | D11: 46202.742 | E11: 46202 | W11: Sí | AB11: Sí | AD11: Sí | AF11: Sí | AV11: Sí | AW11: 2023 | AX11: Sí | AY11: Sí | AZ11: NO SABE | CM11: 4 | CP11: No | CQ11: No | CR11: No | CS11: No | CT11: No | CU11: No | CV11: No | CW11: No | CX11: No | EH11: Sí | EI11: 13.3087066 -88.5708734 0.0 0.0;13.308305945039907 -88.57060186564922 0.0 0.0;13.3080069 -88.5691306 0.0 0.0;13.3077682 -88.569366 0.0 0.0;13.3087066 -88.5708734 0.0 0.0 | EK11: 60259676 | EN11: EMPIEZAN A SEMBRAR PIPIAN Y DESPUES SEMBRARAN MAIZ | ES11: 22208802 | ET11: a5c4ebc3-b10b-4e28-8c95-2fec8cbe7c5f | EU11: 46202.992 | EX11: submitted_via_web | EY11: encuestador_adepro | EZ11: vzzpoqrQEmZ8kFXEawwS6F | FB11: uuid:a5c4ebc3-b10b-4e28-8c95-2fec8cbe7c5f | FC11: 5
A12: ="V"&B12&"-R"&FC12 -> V2-R6 | B12: 2 | C12: 46202.402 | D12: 46203.336 | E12: 46202 | G12: Zaira | H12: Milagro | I12: 46202 | K12: JOSE ESTANISLAO RODRIGUEZ | L12: 69 | M12: Hombre | O12: Usulután | P12: Usulután Oeste | Q12: Jiquilisco | R12: CANTON LA NORIA | S12: LA MARANONERA | V12: WENDY RODRIGUEZ | W12: Sí | Y12: Familiar del productor | AB12: Sí | AD12: No | AF12: Sí | AG12: 1 | AH12: 2 | AI12: 1 | AJ12: 200 | AN12: 500 | AV12: Sí | AW12: 2023 | AX12: Sí | AY12: Sí | AZ12: FRANCISCO | BA12: Sí | BO12: Tractor Arado Rastra Cultivadora Sembradora Podadora Equipo de fumigación | BP12: 1 | BQ12: 1 | BR12: 1 | BS12: 1 | BT12: 1 | BU12: 1 | BV12: 0 | BW12: 0 | BX12: 0 | BY12: 0 | BZ12: 0 | CA12: 0 | CB12: 0 | CC12: Sequías | CD12: 0 | CE12: 1 | CF12: 0 | CG12: 0 | CH12: 0 | CI12: 0 | CJ12: 0 | CK12: 0 | CL12: 0 | CM12: 5 | CO12: Producción agropecuaria | CP12: No | CQ12: No | CR12: No | CS12: No | CT12: No | CU12: No | CV12: No | CW12: No | CX12: Sí | CY12: No | CZ12: No | DA12: No | DB12: No | DC12: No | DD12: No | DE12: No | DG12: 7 | DH12: 7 | DI12: 7 | DJ12: 3 | DK12: 7 | DL12: 7 | DM12: 7 | DN12: 7 | DO12: Sí | DP12: Agua entubada | DR12: Sí | DS12: Sí | DT12: Ene Feb Mar Abr May Jun Jul Ago Sep Oct Nov Dic | DU12: 1 | DV12: 1 | DW12: 1 | DX12: 1 | DY12: 1 | DZ12: 1 | EA12: 1 | EB12: 1 | EC12: 1 | ED12: 1 | EE12: 1 | EF12: 1 | EH12: Sí | EI12: 13.3872594 -88.678072 0.0 0.0; 13.3873038 -88.6779345 0.0 0.0; 13.3876548 -88.6778923 0.0 0.0; 13.3876391 -88.6780116 0.0 0.0; 13.3872594 -88.678072 0.0 0.0 | EK12: 76169140 | EN12: LA HIJA ES BENEFICIARIA | ES12: 22217390 | ET12: 09e653af-0ea9-44a4-b386-4db9c752e2ec | EU12: 46203.586 | EX12: submitted_via_web | EY12: encuestador_adepro | EZ12: vzzpoqrQEmZ8kFXEawwS6F | FB12: uuid:09e653af-0ea9-44a4-b386-4db9c752e2ec | FC12: 6
A13: ="V"&B13&"-R"&FC13 -> V2-R7 | B13: 2 | C13: 46202.42 | D13: 46202.439 | E13: 46202 | G13: Wendy | H13: Rigoberto | I13: 46202 | K13: NHEMY DEL CARMEN GOMEZ CANAS | L13: 50 | M13: Mujer | O13: San Miguel | P13: San Miguel Centro | Q13: San Miguel | R13: CANTON PRIMAVERA EL TRANSITO | S13: PRIMAVERA | V13: NOHEMY GARCIA | W13: Sí | Y13: Productor | AB13: Sí | AD13: No | AF13: Sí | AG13: 2 | AH13: 20 | AI13: 2 | AJ13: 700 | AK13: 18 | AM13: 10 | AN13: 600 | AV13: Sí | AW13: 2021 | AX13: Sí | AY13: Sí | AZ13: LUIS | BA13: Sí | BB13: Regeneración artificial (plantación de árboles) | BC13: No | BD13: Sí | BE13: RECLIMA ONG | BF13: 0 | BG13: 1 | BH13: 0 | BI13: 1 | BJ13: 0 | BK13: 0 | BL13: Aumentó mucho | BM13: Sequías extremas | BO13: Rastra Bomba de agua | BP13: 0 | BQ13: 1 | BR13: 0 | BS13: 0 | BT13: 0 | BU13: 0 | BV13: 0 | BW13: 1 | BX13: 0 | BY13: 0 | BZ13: 0 | CA13: 0 | CB13: 0 | CC13: Sequías | CD13: 0 | CE13: 1 | CF13: 0 | CG13: 0 | CH13: 0 | CI13: 0 | CJ13: 0 | CK13: 0 | CL13: 0 | CM13: 3 | CP13: Sí | CQ13: Sí | CR13: No | CS13: Sí | CT13: No | CU13: Sí | CV13: No | CW13: No | CX13: No | DG13: 4 | DH13: 7 | DI13: 2 | DJ13: 7 | DK13: 7 | DM13: 7 | DO13: Sí | EH13: Sí | EI13: PENDIENTE | EK13: 70901542 | EN13: NINGUNA | ES13: 22218815 | ET13: 9d47a5d0-8b09-4fa9-b01f-233bb0700fa5 | EU13: 46203.626 | EX13: submitted_via_web | EY13: encuestador_adepro | EZ13: vzzpoqrQEmZ8kFXEawwS6F | FB13: uuid:9d47a5d0-8b09-4fa9-b01f-233bb0700fa5 | FC13: 7
A14: ="V"&B14&"-R"&FC14 -> V2-R9 | B14: 2 | C14: 46202.442 | D14: 46202.457 | E14: 46202 | G14: Wendy | K14: NOHEMY HERNANDEZ | L14: 50 | M14: Mujer | O14: San Miguel | P14: San Miguel Centro | W14: Sí | AB14: Sí | AD14: No | AF14: No | EH14: Sí | EI14: 13.3517716 -88.3129451 0.0 0.0;13.366207480874408 -88.30100432038307 0.0 0.0;13.3516734 -88.3126581 0.0 0.0;13.38270582382977 -88.31388127058744 0.0 0.0;13.370796012408158 -88.32492057234049 0.0 0.0;13.360910027285502 -88.33363708108664 0.0 0.0;13.35930315352596 -88.32394257187843 0.0 0.0;13.3516734 -88.3126581 0.0 0.0;13.354877834419723 -88.31916455179453 0.0 0.0;13.344480331347976 -88.32389261573553 0.0 0.0;13.3516734 -88.3126581 0.0 0.0;13.354877834419723 -88.31916455179453 0.0 0.0;13.3516832424863 -88.32698956131935 0.0 0.0;13.3517716 -88.3129451 0.0 0.0 | EK14: 70901542 | EN14: MEDICION NOHEMY | ES14: 22218817 | ET14: acd3087f-99f7-4159-b895-d99fd8954ce0 | EU14: 46203.626 | EX14: submitted_via_web | EY14: encuestador_adepro | EZ14: vzzpoqrQEmZ8kFXEawwS6F | FB14: uuid:acd3087f-99f7-4159-b895-d99fd8954ce0 | FC14: 9
A15: ="V"&B15&"-R"&FC15 -> V2-R10 | B15: 2 | C15: 46202.48 | D15: 46203.376 | E15: 46202 | G15: Wendy | H15: Rigoberto | I15: 46202 | K15: MARIA DE JESUS RIVAS LISAMA | L15: 37 | M15: Mujer | O15: San Miguel | P15: San Miguel Centro | Q15: San Miguel | R15: CANTON PRIMAVERA | S15: CASERIO MI ANGULO | V15: MARIA RIVAS LISAMA | W15: Sí | Y15: Productor | AB15: Sí | AD15: No | AF15: Sí | AG15: 1 | AH15: 1 | AI15: 1 | AJ15: 60 | AK15: 250 | AL15: 50 | AM15: 10 | AN15: 500 | AV15: Sí | AW15: 2022 | AX15: No | AY15: No | BA15: No | BO15: Ningún activo | BP15: 0 | BQ15: 0 | BR15: 0 | BS15: 0 | BT15: 0 | BU15: 0 | BV15: 0 | BW15: 0 | BX15: 0 | BY15: 0 | BZ15: 0 | CA15: 0 | CB15: 1 | CC15: Lluvia o inundaciones | CD15: 0 | CE15: 0 | CF15: 1 | CG15: 0 | CH15: 0 | CI15: 0 | CJ15: 0 | CK15: 0 | CL15: 0 | CM15: 6 | CO15: Oficios varios (artesanías, carpintería, albañilería, etc.) | CP15: Sí | CQ15: No | CR15: No | CS15: No | CT15: No | CU15: No | CV15: No | CW15: No | CX15: Sí | CY15: No | CZ15: No | DA15: No | DB15: No | DC15: No | DD15: No | DE15: No | DG15: 4 | DH15: 2 | DI15: 3 | DJ15: 2 | DK15: 7 | DL15: 2 | DM15: 4 | DN15: 2 | DO15: Sí | EH15: Sí | EI15: 13.357721060704327 -88.33317708224058 0.0 0.0; 13.3581517 -88.3280833 0.0 0.0; 13.36168214491333 -88.32408539950848 0.0 0.0; 13.36489193568014 -88.32735233008862 0.0 0.0; 13.366843232724067 -88.33146013319492 0.0 0.0; 13.362531895508418 -88.33362702280283 0.0 0.0; 13.357721060704327 -88.33317708224058 0.0 0.0; 13.35580100587401 -88.3308569714427 0.0 0.0; 13.35630108278788 -88.32847315818071 0.0 0.0; 13.357887751797747 -88.32608465105295 0.0 0.0; 13.359539977249463 -88.32547713071108 0.0 0.0; 13.36168214491333 -88.32408539950848 0.0 0.0; 13.361389542959886 -88.32656778395176 0.0 0.0; 13.364369042800197 -88.32464531064034 0.0 0.0; 13.357721060704327 -88.33317708224058 0.0 0.0 | EK15: 69554723 | EL15: 76000631 | EN15: NINGUNO | ES15: 22218831 | ET15: 7b9380eb-f042-411a-81cb-3d51ad535f36 | EU15: 46203.627 | EX15: submitted_via_web | EY15: encuestador_adepro | EZ15: vzzpoqrQEmZ8kFXEawwS6F | FB15: uuid:7b9380eb-f042-411a-81cb-3d51ad535f36 | FC15: 10
A16: ="V"&B16&"-R"&FC16 -> V2-R11 | B16: 2 | C16: 46202.443 | D16: 46202.466 | E16: 46202 | G16: Rodrigo | H16: Rigoberto | I16: 46202 | K16: MARCO ANTONIO CALDERON GARCIA | L16: 50 | M16: Hombre | V16: MARCO CALDERON | W16: Sí | Y16: Productor | AB16: Sí | AF16: Sí | AG16: 1 | AH16: 1 | AI16: 1 | AJ16: 65 | AK16: 10 | AM16: 240 | AV16: Sí | AW16: 2024 | AX16: Sí | AY16: No | AZ16: ISELA QUINTANILLA | BA16: Sí | BB16: Regeneración artificial (plantación de árboles) | BC16: No | BD16: Sí | BE16: ONG | BF16: 0 | BG16: 0 | BH16: 0 | BI16: 1 | BJ16: 0 | BK16: 0 | BL16: Sin cambió | BM16: Otra, especificar | BN16: FALTA DE AGUA | BO16: Arado | BP16: 0 | BQ16: 0 | BR16: 0 | BS16: 0 | BT16: 0 | BU16: 0 | BV16: 0 | BW16: 0 | BX16: 0 | BY16: 0 | BZ16: 0 | CA16: 0 | CB16: 0 | CC16: Sequías | CD16: 0 | CE16: 1 | CF16: 0 | CG16: 0 | CH16: 0 | CI16: 0 | CJ16: 0 | CK16: 0 | CL16: 0 | CM16: 5 | CO16: Jornalero agropecuario | CP16: Sí | CQ16: Sí | CR16: Sí | CS16: Sí | CT16: No | CU16: Sí | CV16: Sí | CW16: No | CX16: Sí | CY16: Sí | CZ16: Sí | DA16: No | DB16: No | DC16: No | DD16: No | DE16: No | DG16: 5 | DH16: 4 | DI16: 0 | DJ16: 0 | DK16: 5 | DL16: 1 | DM16: 7 | DN16: 0 | DO16: Sí | DP16: Agua entubada | DR16: Sí | DS16: Sí | DT16: Ene Feb Mar Abr May Jun Jul Ago Sep Oct Nov Dic | DU16: 1 | DV16: 1 | DW16: 1 | DX16: 1 | DY16: 1 | DZ16: 1 | EA16: 1 | EB16: 1 | EC16: 1 | ED16: 1 | EE16: 1 | EF16: 1 | EH16: Sí | EI16: 13.3621856 -88.3216157 0.0 0.0;13.362157 -88.3217061 0.0 0.0;13.361951 -88.3216423 0.0 0.0;13.3620381 -88.3213908 0.0 0.0;13.3622319 -88.32135 0.0 0.0;13.3621856 -88.3216157 0.0 0.0 | EL16: 60163628 | EN16: PERDIO LA COSECHA DE FRIJOL | ES16: 22237409 | ET16: 5abdf5c2-add7-4462-8faf-09ebaf783be9 | EU16: 46204.66 | EX16: submitted_via_web | EY16: encuestador_adepro | EZ16: vzzpoqrQEmZ8kFXEawwS6F | FB16: uuid:5abdf5c2-add7-4462-8faf-09ebaf783be9 | FC16: 11
A17: ="V"&B17&"-R"&FC17 -> V2-R12 | B17: 2 | C17: 46202.471 | D17: 46202.485 | E17: 46202 | G17: Rodrigo | H17: Rigoberto | I17: 46202 | K17: CLAUDIA AZUCENA CAMPOS | L17: 36 | M17: Mujer | O17: San Miguel | P17: San Miguel Oeste | Q17: El Transito | R17: EL LLANO | S17: CASERIO LA CEIBA | V17: CLAUDIA CAMPOS | W17: Sí | Y17: Productor | AB17: Sí | AD17: No | AF17: Sí | AG17: 1 | AH17: 2 | AI17: 1 | AJ17: 100 | AK17: 250 | AL17: 100 | AN17: 600 | AV17: Sí | AW17: 2024 | AX17: Sí | AY17: No | AZ17: ISELA QUINTANILLA | BA17: Sí | BB17: Regeneración artificial (plantación de árboles) | BC17: No | BD17: Sí | BE17: ONG | BF17: 0 | BG17: 0 | BH17: 0 | BI17: 1 | BJ17: 0 | BK17: 0 | BL17: Sin cambió | BM17: Sequías extremas | BO17: Equipo de fumigación | BP17: 0 | BQ17: 0 | BR17: 0 | BS17: 0 | BT17: 0 | BU17: 1 | BV17: 0 | BW17: 0 | BX17: 0 | BY17: 0 | BZ17: 0 | CA17: 0 | CB17: 0 | CC17: No sufrió pérdidas de cosecha o animales | CD17: 0 | CE17: 0 | CF17: 0 | CG17: 0 | CH17: 0 | CI17: 0 | CJ17: 0 | CK17: 0 | CL17: 1 | CM17: 4 | CO17: Trabajo asalariado/permanente (sueldo regular) | CP17: No | CQ17: No | CR17: No | CS17: No | CT17: No | CU17: No | CV17: No | CW17: No | CX17: Sí | CY17: No | CZ17: No | DA17: No | DB17: No | DC17: No | DD17: No | DE17: No | DG17: 7 | DH17: 5 | DI17: 3 | DJ17: 7 | DK17: 7 | DL17: 3 | DM17: 7 | DN17: 7 | DO17: Sí | DP17: Agua entubada | DR17: Sí | DS17: Sí | DT17: Ene Feb Mar Abr May Jun Jul Ago Sep Oct Nov Dic | DU17: 1 | DV17: 1 | DW17: 1 | DX17: 1 | DY17: 1 | DZ17: 1 | EA17: 1 | EB17: 1 | EC17: 1 | ED17: 1 | EE17: 1 | EF17: 1 | EH17: No | EJ17: Lejanía, dentro del distritio | EK17: 71893551 | EN17: PRODUCCION DE AUTOCONSUMO | ES17: 22237410 | ET17: 49b4d306-077b-44ea-b767-d8c8025a9dd0 | EU17: 46204.66 | EX17: submitted_via_web | EY17: encuestador_adepro | EZ17: vzzpoqrQEmZ8kFXEawwS6F | FB17: uuid:49b4d306-077b-44ea-b767-d8c8025a9dd0 | FC17: 12
A18: ="V"&B18&"-R"&FC18 -> V2-R13 | B18: 2 | C18: 46202.38 | D18: 46204.689 | E18: 46202 | G18: Nancy | H18: Milagro | I18: 46202 | K18: JOSE JAVIER LOPEZ RIVERA | L18: 34 | M18: Hombre | O18: Usulután | P18: Usulután Oeste | Q18: Jiquilisco | R18: EL QUINAL | S18: ANDRES CHAVEZ | V18: JAVIER LOPEZ | W18: Sí | Y18: Productor | AB18: Sí | AD18: Sí | AF18: Sí | AG18: 1 | AH18: 2 | AI18: 1 | AJ18: 50 | AK18: 300 | AL18: 100 | AM18: 160 | AN18: 600 | AV18: Sí | AW18: 2023 | AX18: Sí | AY18: No | AZ18: MAIRA FELICITA VIGIL | BA18: No | BO18: Tanque para almacenamiento de agua | BP18: 0 | BQ18: 0 | BR18: 0 | BS18: 0 | BT18: 0 | BU18: 0 | BV18: 1 | BW18: 0 | BX18: 0 | BY18: 0 | BZ18: 0 | CA18: 0 | CB18: 0 | CC18: Sequías | CD18: 0 | CE18: 1 | CF18: 0 | CG18: 0 | CH18: 0 | CI18: 0 | CJ18: 0 | CK18: 0 | CL18: 0 | CM18: 4 | CO18: Trabajo asalariado/permanente (sueldo regular) | CP18: No | CQ18: No | CR18: Sí | CS18: Sí | CT18: No | CU18: Sí | CV18: No | CW18: No | CX18: No | DG18: 2 | DH18: 1 | DI18: 1 | DJ18: 2 | DK18: 7 | DL18: 2 | DM18: 1 | DN18: 1 | DO18: Sí | DP18: Agua entubada | DR18: No | DS18: No | DT18: Ene Feb Mar Abr May Jun Jul Ago Sep Oct Nov Dic | DU18: 1 | DV18: 1 | DW18: 1 | DX18: 1 | DY18: 1 | DZ18: 1 | EA18: 1 | EB18: 1 | EC18: 1 | ED18: 1 | EE18: 1 | EF18: 1 | EH18: Sí | EI18: 13.383103 -88.6711989 0.0 0.0; 13.3829272 -88.6704652 0.0 0.0; 13.3835793 -88.6703437 0.0 0.0; 13.3837088 -88.6711024 0.0 0.0; 13.383103 -88.6711989 0.0 0.0 | EK18: 70993454 | EN18: IDENTIFICA EL PROGRAMA Y LAS CAPACITACIONES QUE RECIBIO EN LA ACTUALIDAD TIENE CULTIVO DE LOROCO | ES18: 22241416 | ET18: 3af9b4dc-3abe-4559-bbd5-4c4cc09ddb0d | EU18: 46204.939 | EX18: submitted_via_web | EY18: encuestador_adepro | EZ18: vzzpoqrQEmZ8kFXEawwS6F | FB18: uuid:3af9b4dc-3abe-4559-bbd5-4c4cc09ddb0d | FC18: 13
A19: ="V"&B19&"-R"&FC19 -> V2-R14 | B19: 2 | C19: 46202.418 | D19: 46204.689 | E19: 46202 | G19: Nancy | H19: Milagro | I19: 46202 | K19: MERCEDES CATALINA CASTANEDA | L19: 71 | M19: Mujer | O19: Usulután | P19: Usulután Oeste | Q19: Jiquilisco | R19: TIERRA BLANCA | S19: TIERRA BLANCA | V19: MERCEDES CATALINA CASTANEDA | W19: Sí | Y19: Productor | AB19: Sí | AD19: Sí | AF19: Sí | AG19: 1 | AH19: 1 | AI19: 1 | AJ19: 50 | AK19: 300 | AL19: 30 | AM19: 300 | AV19: Sí | AW19: 2024 | AX19: Sí | AY19: Sí | AZ19: MAIRA FELICITA VIGIL | BA19: Sí | BB19: Regeneración artificial (plantación de árboles) | BC19: Sí | BD19: Sí | BE19: ONG | BF19: 0 | BG19: 0 | BH19: 0 | BI19: 1 | BJ19: 0 | BK19: 0 | BL19: Aumentó algo | BM19: Sequías extremas | BO19: Ningún activo | BP19: 0 | BQ19: 0 | BR19: 0 | BS19: 0 | BT19: 0 | BU19: 0 | BV19: 0 | BW19: 0 | BX19: 0 | BY19: 0 | BZ19: 0 | CA19: 0 | CB19: 1 | CC19: Sequías | CD19: 0 | CE19: 1 | CF19: 0 | CG19: 0 | CH19: 0 | CI19: 0 | CJ19: 0 | CK19: 0 | CL19: 0 | CM19: 1 | CO19: Remesas familiares | CP19: No | CQ19: No | CR19: No | CS19: No | CT19: No | CU19: No | CV19: No | CW19: No | CX19: No | DG19: 7 | DH19: 7 | DI19: 7 | DJ19: 0 | DK19: 3 | DL19: 7 | DM19: 7 | DN19: 7 | DO19: Sí | DP19: Agua entubada | DR19: Sí | DS19: Sí | DT19: Ene Feb Mar Abr May Jun Jul Ago Sep Oct Nov Dic | DU19: 1 | DV19: 1 | DW19: 1 | DX19: 1 | DY19: 1 | DZ19: 1 | EA19: 1 | EB19: 1 | EC19: 1 | ED19: 1 | EE19: 1 | EF19: 1 | EH19: Sí | EI19: 13.3914827 -88.6721747 0.0 0.0; 13.3917562 -88.6737844 0.0 0.0; 13.3912361 -88.6737714 0.0 0.0; 13.391086 -88.6721066 0.0 0.0; 13.3914827 -88.6721747 0.0 0.0 | EK19: 71918633 | ES19: 22241417 | ET19: 53b6be23-f68c-44be-827f-ae26d0d1b939 | EU19: 46204.939 | EX19: submitted_via_web | EY19: encuestador_adepro | EZ19: vzzpoqrQEmZ8kFXEawwS6F | FB19: uuid:53b6be23-f68c-44be-827f-ae26d0d1b939 | FC19: 14
A20: ="V"&B20&"-R"&FC20 -> V2-R15 | B20: 2 | C20: 46202.374 | D20: 46202.417 | E20: 46202 | G20: Iván | H20: Milagro | I20: 46202 | K20: SANTOS LORENZO DEL CID ZELAYA | L20: 45 | M20: Hombre | O20: Usulután | P20: Usulután Oeste | Q20: Jiquilisco | R20: ZAMORAN | S20: EL CEDRO | V20: SANTOS ZELAYA | W20: Sí | Y20: Productor | AB20: Sí | AF20: Sí | AG20: 1 | AH20: 4 | AI20: 1 | AK20: 200 | AL20: 160 | AM20: 350 | AN20: 1200 | AV20: Sí | AW20: 2024 | AX20: Sí | AY20: Sí | AZ20: SALVADOR | BA20: No | BO20: Bomba de agua Equipo para la cría o engorda de animales Autos particulares Bodega | BP20: 0 | BQ20: 0 | BR20: 0 | BS20: 0 | BT20: 0 | BU20: 0 | BV20: 0 | BW20: 1 | BX20: 1 | BY20: 1 | BZ20: 0 | CA20: 1 | CB20: 0 | CC20: Lluvia o inundaciones Plagas o enfermedades | CD20: 1 | CE20: 0 | CF20: 1 | CG20: 0 | CH20: 0 | CI20: 0 | CJ20: 0 | CK20: 0 | CL20: 0 | CM20: 5 | CO20: Producción agropecuaria | CP20: Sí | CQ20: No | CR20: Sí | CS20: Sí | CT20: No | CU20: No | CV20: Sí | CW20: No | CX20: Sí | CY20: No | CZ20: Sí | DA20: No | DB20: No | DC20: Sí | DD20: No | DE20: No | DG20: 7 | DH20: 3 | DI20: 5 | DJ20: 5 | DK20: 4 | DL20: 7 | DM20: 7 | DN20: 7 | DO20: Sí | DP20: Agua entubada | DR20: Sí | DS20: No | DT20: Ene Feb Mar Abr Jun Jul May Ago Sep Oct Nov Dic | DU20: 1 | DV20: 1 | DW20: 1 | DX20: 1 | DY20: 1 | DZ20: 1 | EA20: 1 | EB20: 1 | EC20: 1 | ED20: 1 | EE20: 1 | EF20: 1 | EH20: Sí | EI20: 13.31827 -88.7063505 0.0 0.0; 13.3179185 -88.7064647 0.0 0.0; 13.3184554 -88.7013528 0.0 0.0; 13.3189528 -88.7014116 0.0 0.0; 13.31827 -88.7063505 0.0 0.0 | EK20: 75747522 | EN20: CUARENTA VARIEDADES DE ARBOLES FRITAS | ES20: 22324081 | ET20: d4910001-71ec-4ff0-8292-9629eda9b27e | EU20: 46211.127 | EX20: submitted_via_web | EY20: encuestador_adepro | EZ20: vzzpoqrQEmZ8kFXEawwS6F | FB20: uuid:d4910001-71ec-4ff0-8292-9629eda9b27e | FC20: 15
A21: ="V"&B21&"-R"&FC21 -> V2-R16 | B21: 2 | C21: 46202.423 | D21: 46202.453 | E21: 46202 | G21: Iván | H21: Milagro | I21: 46202 | K21: CANDIDA ZELAYA DEL CID | L21: 72 | M21: Mujer | O21: Usulután | P21: Usulután Oeste | Q21: Jiquilisco | R21: EL ZAMORANO | S21: EL CEDRO | V21: CANDIDA ZELAYA | W21: Sí | Y21: Productor | AB21: Sí | AD21: Sí | AF21: Sí | AG21: 2 | AH21: 3 | AI21: 2 | AJ21: 40 | AK21: 35 | AL21: 35 | AM21: 100 | AV21: Sí | AW21: 2024 | AX21: Sí | AY21: Sí | AZ21: SALVADOR GOMEZ | BA21: Sí | BB21: Regeneración artificial (plantación de árboles) | BC21: No | BD21: Sí | BE21: RECLIMA | BF21: 0 | BG21: 1 | BH21: 0 | BI21: 0 | BJ21: 0 | BK21: 0 | BL21: Sin cambió | BM21: Sequías extremas | BO21: Equipo de fumigación | BP21: 0 | BQ21: 0 | BR21: 0 | BS21: 0 | BT21: 0 | BU21: 1 | BV21: 0 | BW21: 0 | BX21: 0 | BY21: 0 | BZ21: 0 | CA21: 0 | CB21: 0 | CC21: Sequías | CD21: 0 | CE21: 1 | CF21: 0 | CG21: 0 | CH21: 0 | CI21: 0 | CJ21: 0 | CK21: 0 | CL21: 0 | CM21: 2 | CO21: Jornalero agropecuario | CP21: Sí | CQ21: Sí | CR21: Sí | CS21: Sí | CT21: No | CU21: Sí | CV21: No | CW21: No | CX21: No | DG21: 4 | DH21: 7 | DI21: 2 | DJ21: 7 | DK21: 7 | DL21: 7 | DM21: 7 | DN21: 7 | DO21: Sí | DP21: Agua entubada | DR21: Sí | DS21: No | DT21: Ene Feb Mar Abr May Jun Jul Ago Sep Oct Nov Dic | DU21: 1 | DV21: 1 | DW21: 1 | DX21: 1 | DY21: 1 | DZ21: 1 | EA21: 1 | EB21: 1 | EC21: 1 | ED21: 1 | EE21: 1 | EF21: 1 | EH21: Sí | EI21: 13.317562 -88.6994162 0.0 0.0;13.317079 -88.6993005 0.0 0.0;13.3167429 -88.699978 0.0 0.0;13.317251 -88.7001076 0.0 0.0;13.317562 -88.6994162 0.0 0.0 | EK21: 73422704 | ES21: 22324202 | ET21: 4e002817-e8cf-41fb-b6bf-63dd4c5f272d | EU21: 46211.13 | EX21: submitted_via_web | EY21: encuestador_adepro | EZ21: vzzpoqrQEmZ8kFXEawwS6F | FB21: uuid:4e002817-e8cf-41fb-b6bf-63dd4c5f272d | FC21: 16
A22: ="V"&B22&"-R"&FC22 -> V2-R17 | B22: 2 | C22: 46202.468 | D22: 46210.627 | E22: 46202 | G22: Iván | H22: Milagro | I22: 46202 | K22: NOE ABRAHAN MARTINEZ GALVEZ | L22: 37 | M22: Hombre | O22: Usulután | P22: Usulután Oeste | Q22: Jiquilisco | R22: ZAMORANO | S22: LOS ZAMORANOS | T22: NK-574-0 | V22: NOE MARTINEZ | W22: Sí | Y22: Productor | AB22: Sí | AD22: No | AF22: Sí | AG22: 1 | AH22: 1 | AI22: 1 | AJ22: 60 | AK22: 40 | AL22: 17 | AM22: 100 | AV22: Sí | AW22: 2021 | AX22: No | AY22: No | BA22: No | BO22: Ningún activo | BP22: 0 | BQ22: 0 | BR22: 0 | BS22: 0 | BT22: 0 | BU22: 0 | BV22: 0 | BW22: 0 | BX22: 0 | BY22: 0 | BZ22: 0 | CA22: 0 | CB22: 1 | CC22: Sequías | CD22: 0 | CE22: 1 | CF22: 0 | CG22: 0 | CH22: 0 | CI22: 0 | CJ22: 0 | CK22: 0 | CL22: 0 | CM22: 3 | CO22: Jornalero agropecuario | CP22: Sí | CQ22: No | CR22: Sí | CS22: Sí | CT22: Sí | CU22: Sí | CV22: Sí | CW22: No | CX22: Sí | CY22: Sí | CZ22: Sí | DA22: No | DB22: Sí | DC22: Sí | DD22: No | DE22: No | DG22: 7 | DH22: 0 | DI22: 3 | DJ22: 6 | DK22: 7 | DL22: 6 | DM22: 7 | DN22: 2 | DO22: Sí | EH22: No | EJ22: Otra | EK22: 72502406 | EN22: NO SE PUDO MEDIR LA PARCELA POR QUE NO EL PRODUCTOR YA NO TIENE ACCESO | ES22: 22324888 | ET22: 142ea5f0-fe95-45c7-b4b6-897f9ccd4532 | EU22: 46211.152 | EX22: submitted_via_web | EY22: encuestador_adepro | EZ22: vzzpoqrQEmZ8kFXEawwS6F | FB22: uuid:142ea5f0-fe95-45c7-b4b6-897f9ccd4532 | FC22: 17
A23: ="V"&B23&"-R"&FC23 -> V2-R18 | B23: 2 | C23: 46202.547 | D23: 46202.57 | E23: 46202 | G23: Iván | H23: Milagro | I23: 46202 | K23: DUGLAS TURCIO ESCOBAR | L23: 62 | M23: Hombre | O23: Usulután | P23: Usulután Oeste | Q23: San Francisco Javier | R23: JOBALHORNOS | V23: DOUGLAS TURCIOS | W23: Sí | Y23: Productor | AB23: Sí | AF23: Sí | AG23: 1 | AH23: 2 | AI23: 1 | AJ23: 150 | AK23: 100 | AL23: 42 | AM23: 50 | AV23: Sí | AW23: 2023 | AX23: No | AY23: No | BA23: No | BO23: Ningún activo | BP23: 0 | BQ23: 0 | BR23: 0 | BS23: 0 | BT23: 0 | BU23: 0 | BV23: 0 | BW23: 0 | BX23: 0 | BY23: 0 | BZ23: 0 | CA23: 0 | CB23: 1 | CC23: Plagas o enfermedades Sequías Lluvia o inundaciones | CD23: 1 | CE23: 1 | CF23: 1 | CG23: 0 | CH23: 0 | CI23: 0 | CJ23: 0 | CK23: 0 | CL23: 0 | CM23: 4 | CO23: Oficios varios (artesanías, carpintería, albañilería, etc.) | CP23: No | CQ23: No | CR23: No | CS23: Sí | CT23: No | CU23: No | CV23: No | CW23: No | CX23: Sí | CY23: Sí | CZ23: Sí | DA23: No | DB23: No | DC23: No | DD23: No | DE23: No | DG23: 7 | DH23: 5 | DI23: 4 | DJ23: 5 | DK23: 0 | DL23: 7 | DM23: 7 | DN23: 7 | DO23: Sí | EH23: Sí | EI23: 13.3956902 -88.600342 0.0 0.0;13.3954745 -88.6005548 0.0 0.0;13.3953811 -88.6007926 0.0 0.0;13.3945143 -88.6007487 0.0 0.0;13.3944814 -88.600552 0.0 0.0;13.3945455 -88.6005437 0.0 0.0;13.3944554 -88.600416 0.0 0.0;13.394423 -88.6002722 0.0 0.0;13.3956902 -88.600342 0.0 0.0 | EK23: 61010116 | EL23: 71590170 | ES23: 22325160 | ET23: 866a0396-2c78-4616-ba19-d82f102f58c3 | EU23: 46211.167 | EX23: submitted_via_web | EY23: encuestador_adepro | EZ23: vzzpoqrQEmZ8kFXEawwS6F | FB23: uuid:866a0396-2c78-4616-ba19-d82f102f58c3 | FC23: 18
A24: ="V"&B24&"-R"&FC24 -> V3-R3 | B24: 3 | C24: 46202.496 | D24: 46202.557 | E24: 46201 | G24: Javier | H24: Milagro | I24: 46202 | K24: OLIVAR BATRES JOVITO NELSON | L24: 50 | M24: Hombre | O24: Usulután | P24: Usulután Oeste | Q24: Jiquilisco | R24: NUEVO TABLON | V24: OLIVER BATRES JOVITO NELSON | W24: Sí | Y24: Productor | AB24: Sí | AD24: Sí | AF24: Sí | AG24: 1 | AH24: 2 | AI24: 1 | AJ24: 100 | AK24: 180 | AL24: 50 | AM24: 70 | AN24: 1000 | AO24: Bovinos (vacas, terneros, novillos, bueyes, toros) | AP24: 1 | AQ24: 0 | AR24: 0 | AS24: 0 | AT24: 0 | AV24: Sí | AW24: 2025 | AX24: Sí | AY24: No | AZ24: JENNIFER AREVALO | BA24: Sí | BB24: Regeneración artificial (plantación de árboles) | BC24: No | BD24: No | BL24: Aumentó algo | BM24: Falta de mantenimiento | BO24: Ningún activo | BP24: 0 | BQ24: 0 | BR24: 0 | BS24: 0 | BT24: 0 | BU24: 0 | BV24: 0 | BW24: 0 | BX24: 0 | BY24: 0 | BZ24: 0 | CA24: 0 | CB24: 1 | CC24: No sufrió pérdidas de cosecha o animales | CD24: 0 | CE24: 0 | CF24: 0 | CG24: 0 | CH24: 0 | CI24: 0 | CJ24: 0 | CK24: 0 | CL24: 1 | CM24: 2 | CO24: Oficios varios (artesanías, carpintería, albañilería, etc.) | CP24: Sí | CQ24: Sí | CR24: Sí | CS24: Sí | CT24: No | CU24: No | CV24: Sí | CW24: No | CX24: No | DG24: 7 | DH24: 6 | DI24: 2 | DJ24: 1 | DK24: 7 | DL24: 7 | DM24: 7 | DN24: 3 | DO24: Sí | DP24: Agua entubada | DR24: Sí | DS24: Sí | DT24: May | DU24: 0 | DV24: 0 | DW24: 0 | DX24: 0 | DY24: 1 | DZ24: 0 | EA24: 0 | EB24: 0 | EC24: 0 | ED24: 0 | EE24: 0 | EF24: 0 | EH24: No | EJ24: Lejanía, dentro del distritio | EK24: 60100928 | EN24: EL GANADO ERA DEL VECINO COMO TAL | ES24: 22207036 | ET24: fb77112e-6433-483e-a69a-9b6dbd6b1ff2 | EU24: 46202.807 | EX24: submitted_via_web | EZ24: vmzueHpYT9juc6BY6BECkZ | FB24: uuid:fb77112e-6433-483e-a69a-9b6dbd6b1ff2 | FC24: 3
A25: ="V"&B25&"-R"&FC25 -> V3-R4 | B25: 3 | C25: 46202.619 | D25: 46202.638 | E25: 46201 | G25: Zaira | H25: Milagro | I25: 46202 | K25: MANUEL DE JESUS URQUILLA HENRIQUE | L25: 39 | M25: Hombre | O25: Usulután | P25: Usulután Oeste | Q25: San Francisco Javier | R25: BARRIO EL CALVARIO | S25: SAN FRANCISCO JAVIER | V25: REYNA ISABEL HERNANDEZ | W25: Sí | Y25: Familiar del productor | AB25: Sí | AD25: No | AF25: Sí | AG25: 1 | AH25: 2 | AI25: 1 | AJ25: 150 | AK25: 0 | AL25: 40 | AM25: 0 | AN25: 0 | AV25: Sí | AW25: 2020 | AX25: Sí | AY25: No | AZ25: NO SE ACUERDA | BA25: No | BO25: Ningún activo | BP25: 0 | BQ25: 0 | BR25: 0 | BS25: 0 | BT25: 0 | BU25: 0 | BV25: 0 | BW25: 0 | BX25: 0 | BY25: 0 | BZ25: 0 | CA25: 0 | CB25: 1 | CC25: No sufrió pérdidas de cosecha o animales | CD25: 0 | CE25: 0 | CF25: 0 | CG25: 0 | CH25: 0 | CI25: 0 | CJ25: 0 | CK25: 0 | CL25: 1 | CM25: 4 | CO25: Producción agropecuaria | CP25: Sí | CQ25: Sí | CR25: Sí | CS25: No | CT25: No | CU25: No | CV25: No | CW25: No | CX25: Sí | CY25: No | CZ25: No | DA25: No | DB25: No | DC25: No | DD25: No | DE25: No | DG25: 7 | DH25: 2 | DI25: 3 | DJ25: 5 | DK25: 3 | DL25: 7 | DM25: 7 | DN25: 3 | DO25: No | EH25: No | EJ25: Lejanía, dentro del distritio | EK25: 61974206 | EN25: LA PARCELA ESTA LEJOS | ES25: 22207591 | ET25: 7f2ef08c-9fe8-45ad-b693-114c17f3ec14 | EU25: 46202.888 | EX25: submitted_via_web | EZ25: vmzueHpYT9juc6BY6BECkZ | FB25: uuid:7f2ef08c-9fe8-45ad-b693-114c17f3ec14 | FC25: 4
A26: ="V"&B26&"-R"&FC26 -> V3-R5 | B26: 3 | C26: 46202.762 | D26: 46202.779 | E26: 46201 | G26: Milagro | H26: Milagro | I26: 46202 | K26: NUMAS MENA | L26: 51 | M26: Hombre | O26: Usulután | P26: Usulután Oeste | Q26: Jiquilisco | R26: CABOS NEGROS | S26: MARANON | V26: NUMAS | W26: Sí | Y26: Productor | AB26: Sí | AD26: No | AF26: Sí | AG26: 3 | AH26: 3 | AI26: 2 | AJ26: 1400 | AK26: 9999 | AL26: 9999 | AM26: 200 | AN26: 9999 | AV26: Sí | AW26: 2024 | AX26: No | AY26: No | AZ26: NO SABE | BA26: No | BO26: Rastra Equipo de fumigación | BP26: 0 | BQ26: 1 | BR26: 0 | BS26: 0 | BT26: 0 | BU26: 1 | BV26: 0 | BW26: 0 | BX26: 0 | BY26: 0 | BZ26: 0 | CA26: 0 | CB26: 0 | CC26: No sufrió pérdidas de cosecha o animales | CD26: 0 | CE26: 0 | CF26: 0 | CG26: 0 | CH26: 0 | CI26: 0 | CJ26: 0 | CK26: 0 | CL26: 1 | CM26: 3 | CO26: Producción agropecuaria | CP26: No | CQ26: No | CR26: No | CS26: No | CT26: No | CU26: No | CV26: No | CW26: No | CX26: No | DG26: 7 | DH26: 7 | DI26: 0 | DJ26: 2 | DK26: 2 | DL26: 2 | DM26: 7 | DN26: 7 | DO26: Sí | DP26: Agua entubada | DR26: Sí | DS26: Sí | DT26: Ene Feb Mar Abr May Jun Jul Ago Sep Oct Nov Dic | DU26: 1 | DV26: 1 | DW26: 1 | DX26: 1 | DY26: 1 | DZ26: 1 | EA26: 1 | EB26: 1 | EC26: 1 | ED26: 1 | EE26: 1 | EF26: 1 | EH26: No | EJ26: Otra | EK26: 76533675 | EN26: NO VIVE EN LA ZONA CABOS | ES26: 22208921 | ET26: 707cc38e-80e9-48ee-bfc3-e898e8180638 | EU26: 46203.029 | EX26: submitted_via_web | EZ26: vmzueHpYT9juc6BY6BECkZ | FB26: uuid:707cc38e-80e9-48ee-bfc3-e898e8180638 | FC26: 5
A27: ="V"&B27&"-R"&FC27 -> V3-R6 | B27: 3 | C27: 46202.638 | D27: 46203.33 | E27: 46201 | G27: Zaira | H27: Milagro | I27: 46202 | K27: MAGDALENA LISBETH AYALA GOMEZ | L27: 32 | M27: Mujer | O27: Usulután | P27: Usulután Oeste | Q27: San Francisco Javier | R27: BARRIO EL CALVARIO | S27: VISTA AL MAR | V27: MAGDALENA | W27: Sí | Y27: Productor | AB27: Sí | AD27: No | AF27: Sí | AG27: 1 | AH27: 1 | AI27: 1 | AJ27: 0 | AK27: 0 | AL27: 0 | AM27: 0 | AN27: 0 | AV27: Sí | AW27: 2021 | AX27: No | AY27: No | AZ27: NO SE ACUERDA | BA27: No | BO27: Tanque para almacenamiento de agua Bomba de agua | BP27: 0 | BQ27: 0 | BR27: 0 | BS27: 0 | BT27: 0 | BU27: 0 | BV27: 1 | BW27: 1 | BX27: 0 | BY27: 0 | BZ27: 0 | CA27: 0 | CB27: 0 | CC27: Lluvia o inundaciones | CD27: 0 | CE27: 0 | CF27: 1 | CG27: 0 | CH27: 0 | CI27: 0 | CJ27: 0 | CK27: 0 | CL27: 0 | CM27: 3 | CO27: Producción agropecuaria | CP27: Sí | CQ27: Sí | CR27: Sí | CS27: No | CT27: No | CU27: No | CV27: No | CW27: No | CX27: Sí | CY27: No | CZ27: No | DA27: No | DB27: No | DC27: No | DD27: No | DE27: No | DG27: 3 | DH27: 1 | DI27: 0 | DJ27: 4 | DK27: 7 | DL27: 7 | DM27: 7 | DN27: 3 | DO27: Sí | DP27: Agua entubada | DR27: Sí | DS27: Sí | DT27: Ene Feb Mar Abr May Jun Jul Ago Sep Oct Nov Dic | DU27: 1 | DV27: 1 | DW27: 1 | DX27: 1 | DY27: 1 | DZ27: 1 | EA27: 1 | EB27: 1 | EC27: 1 | ED27: 1 | EE27: 1 | EF27: 1 | EH27: No | EJ27: Lejanía, dentro del distritio | EK27: 61689446 | ES27: 22217314 | ET27: aee77320-39e5-4b9b-8a2d-4be8ceb4db83 | EU27: 46203.58 | EX27: submitted_via_web | EZ27: vmzueHpYT9juc6BY6BECkZ | FB27: uuid:aee77320-39e5-4b9b-8a2d-4be8ceb4db83 | FC27: 6
